<?xml version="1.0" encoding="UTF-8"?>
<testng-results skipped="4" failed="1" ignored="0" total="6" passed="1">
  <reporter-output>
  </reporter-output>
  <suite name="Default suite" duration-ms="158934" started-at="2018-04-22T06:10:16Z" finished-at="2018-04-22T06:12:55Z">
    <groups>
    </groups>
    <test name="Default test" duration-ms="158934" started-at="2018-04-22T06:10:16Z" finished-at="2018-04-22T06:12:55Z">
      <class name="Test.loginTest">
        <test-method status="PASS" signature="beforeMethod()[pri:0, instance:Test.loginTest@6d64ab]" name="beforeMethod" is-config="true" duration-ms="21418" started-at="2018-04-22T06:10:16Z" finished-at="2018-04-22T06:10:38Z">
          <reporter-output>
          </reporter-output>
        </test-method> <!-- beforeMethod -->
        <test-method status="SKIP" signature="loginTest2()[pri:0, instance:Test.loginTest@6d64ab]" name="loginTest2" duration-ms="9152" started-at="2018-04-22T06:10:38Z" finished-at="2018-04-22T06:10:47Z">
          <exception class="java.lang.AssertionError">
            <message>
              <![CDATA[expected [true] but found [false]]]>
            </message>
            <full-stacktrace>
              <![CDATA[java.lang.AssertionError: expected [true] but found [false]
at org.testng.Assert.fail(Assert.java:96)
at org.testng.Assert.failNotEquals(Assert.java:776)
at org.testng.Assert.assertTrue(Assert.java:44)
at org.testng.Assert.assertTrue(Assert.java:54)
at Test.loginTest.loginTest2(loginTest.java:40)
at sun.reflect.NativeMethodAccessorImpl.invoke0(Native Method)
at sun.reflect.NativeMethodAccessorImpl.invoke(Unknown Source)
at sun.reflect.DelegatingMethodAccessorImpl.invoke(Unknown Source)
at java.lang.reflect.Method.invoke(Unknown Source)
at org.testng.internal.MethodInvocationHelper.invokeMethod(MethodInvocationHelper.java:124)
at org.testng.internal.Invoker.invokeMethod(Invoker.java:580)
at org.testng.internal.Invoker.invokeTestMethod(Invoker.java:716)
at org.testng.internal.Invoker.invokeTestMethods(Invoker.java:988)
at org.testng.internal.TestMethodWorker.invokeTestMethods(TestMethodWorker.java:125)
at org.testng.internal.TestMethodWorker.run(TestMethodWorker.java:109)
at org.testng.TestRunner.privateRun(TestRunner.java:648)
at org.testng.TestRunner.run(TestRunner.java:505)
at org.testng.SuiteRunner.runTest(SuiteRunner.java:455)
at org.testng.SuiteRunner.runSequentially(SuiteRunner.java:450)
at org.testng.SuiteRunner.privateRun(SuiteRunner.java:415)
at org.testng.SuiteRunner.run(SuiteRunner.java:364)
at org.testng.SuiteRunnerWorker.runSuite(SuiteRunnerWorker.java:52)
at org.testng.SuiteRunnerWorker.run(SuiteRunnerWorker.java:84)
at org.testng.TestNG.runSuitesSequentially(TestNG.java:1208)
at org.testng.TestNG.runSuitesLocally(TestNG.java:1137)
at org.testng.TestNG.runSuites(TestNG.java:1049)
at org.testng.TestNG.run(TestNG.java:1017)
at org.testng.remote.AbstractRemoteTestNG.run(AbstractRemoteTestNG.java:114)
at org.testng.remote.RemoteTestNG.initAndRun(RemoteTestNG.java:251)
at org.testng.remote.RemoteTestNG.main(RemoteTestNG.java:77)
]]>
            </full-stacktrace>
          </exception> <!-- java.lang.AssertionError -->
          <reporter-output>
          </reporter-output>
        </test-method> <!-- loginTest2 -->
        <test-method status="PASS" signature="afterMethod()[pri:0, instance:Test.loginTest@6d64ab]" name="afterMethod" is-config="true" duration-ms="3094" started-at="2018-04-22T06:10:47Z" finished-at="2018-04-22T06:10:50Z">
          <reporter-output>
          </reporter-output>
        </test-method> <!-- afterMethod -->
        <test-method status="PASS" signature="beforeMethod()[pri:0, instance:Test.loginTest@6d64ab]" name="beforeMethod" is-config="true" duration-ms="13663" started-at="2018-04-22T06:10:50Z" finished-at="2018-04-22T06:11:04Z">
          <reporter-output>
          </reporter-output>
        </test-method> <!-- beforeMethod -->
        <test-method status="SKIP" signature="loginTest2()[pri:0, instance:Test.loginTest@6d64ab]" name="loginTest2" duration-ms="7198" started-at="2018-04-22T06:11:04Z" finished-at="2018-04-22T06:11:11Z">
          <exception class="java.lang.AssertionError">
            <message>
              <![CDATA[expected [true] but found [false]]]>
            </message>
            <full-stacktrace>
              <![CDATA[java.lang.AssertionError: expected [true] but found [false]
at org.testng.Assert.fail(Assert.java:96)
at org.testng.Assert.failNotEquals(Assert.java:776)
at org.testng.Assert.assertTrue(Assert.java:44)
at org.testng.Assert.assertTrue(Assert.java:54)
at Test.loginTest.loginTest2(loginTest.java:40)
at sun.reflect.NativeMethodAccessorImpl.invoke0(Native Method)
at sun.reflect.NativeMethodAccessorImpl.invoke(Unknown Source)
at sun.reflect.DelegatingMethodAccessorImpl.invoke(Unknown Source)
at java.lang.reflect.Method.invoke(Unknown Source)
at org.testng.internal.MethodInvocationHelper.invokeMethod(MethodInvocationHelper.java:124)
at org.testng.internal.Invoker.invokeMethod(Invoker.java:580)
at org.testng.internal.Invoker.retryFailed(Invoker.java:838)
at org.testng.internal.Invoker.invokeTestMethods(Invoker.java:1009)
at org.testng.internal.TestMethodWorker.invokeTestMethods(TestMethodWorker.java:125)
at org.testng.internal.TestMethodWorker.run(TestMethodWorker.java:109)
at org.testng.TestRunner.privateRun(TestRunner.java:648)
at org.testng.TestRunner.run(TestRunner.java:505)
at org.testng.SuiteRunner.runTest(SuiteRunner.java:455)
at org.testng.SuiteRunner.runSequentially(SuiteRunner.java:450)
at org.testng.SuiteRunner.privateRun(SuiteRunner.java:415)
at org.testng.SuiteRunner.run(SuiteRunner.java:364)
at org.testng.SuiteRunnerWorker.runSuite(SuiteRunnerWorker.java:52)
at org.testng.SuiteRunnerWorker.run(SuiteRunnerWorker.java:84)
at org.testng.TestNG.runSuitesSequentially(TestNG.java:1208)
at org.testng.TestNG.runSuitesLocally(TestNG.java:1137)
at org.testng.TestNG.runSuites(TestNG.java:1049)
at org.testng.TestNG.run(TestNG.java:1017)
at org.testng.remote.AbstractRemoteTestNG.run(AbstractRemoteTestNG.java:114)
at org.testng.remote.RemoteTestNG.initAndRun(RemoteTestNG.java:251)
at org.testng.remote.RemoteTestNG.main(RemoteTestNG.java:77)
]]>
            </full-stacktrace>
          </exception> <!-- java.lang.AssertionError -->
          <reporter-output>
          </reporter-output>
        </test-method> <!-- loginTest2 -->
        <test-method status="PASS" signature="afterMethod()[pri:0, instance:Test.loginTest@6d64ab]" name="afterMethod" is-config="true" duration-ms="2681" started-at="2018-04-22T06:11:11Z" finished-at="2018-04-22T06:11:14Z">
          <reporter-output>
          </reporter-output>
        </test-method> <!-- afterMethod -->
        <test-method status="PASS" signature="beforeMethod()[pri:0, instance:Test.loginTest@6d64ab]" name="beforeMethod" is-config="true" duration-ms="13769" started-at="2018-04-22T06:11:14Z" finished-at="2018-04-22T06:11:27Z">
          <reporter-output>
          </reporter-output>
        </test-method> <!-- beforeMethod -->
        <test-method status="SKIP" signature="loginTest2()[pri:0, instance:Test.loginTest@6d64ab]" name="loginTest2" duration-ms="7648" started-at="2018-04-22T06:11:27Z" finished-at="2018-04-22T06:11:35Z">
          <exception class="java.lang.AssertionError">
            <message>
              <![CDATA[expected [true] but found [false]]]>
            </message>
            <full-stacktrace>
              <![CDATA[java.lang.AssertionError: expected [true] but found [false]
at org.testng.Assert.fail(Assert.java:96)
at org.testng.Assert.failNotEquals(Assert.java:776)
at org.testng.Assert.assertTrue(Assert.java:44)
at org.testng.Assert.assertTrue(Assert.java:54)
at Test.loginTest.loginTest2(loginTest.java:40)
at sun.reflect.NativeMethodAccessorImpl.invoke0(Native Method)
at sun.reflect.NativeMethodAccessorImpl.invoke(Unknown Source)
at sun.reflect.DelegatingMethodAccessorImpl.invoke(Unknown Source)
at java.lang.reflect.Method.invoke(Unknown Source)
at org.testng.internal.MethodInvocationHelper.invokeMethod(MethodInvocationHelper.java:124)
at org.testng.internal.Invoker.invokeMethod(Invoker.java:580)
at org.testng.internal.Invoker.retryFailed(Invoker.java:838)
at org.testng.internal.Invoker.invokeTestMethods(Invoker.java:1009)
at org.testng.internal.TestMethodWorker.invokeTestMethods(TestMethodWorker.java:125)
at org.testng.internal.TestMethodWorker.run(TestMethodWorker.java:109)
at org.testng.TestRunner.privateRun(TestRunner.java:648)
at org.testng.TestRunner.run(TestRunner.java:505)
at org.testng.SuiteRunner.runTest(SuiteRunner.java:455)
at org.testng.SuiteRunner.runSequentially(SuiteRunner.java:450)
at org.testng.SuiteRunner.privateRun(SuiteRunner.java:415)
at org.testng.SuiteRunner.run(SuiteRunner.java:364)
at org.testng.SuiteRunnerWorker.runSuite(SuiteRunnerWorker.java:52)
at org.testng.SuiteRunnerWorker.run(SuiteRunnerWorker.java:84)
at org.testng.TestNG.runSuitesSequentially(TestNG.java:1208)
at org.testng.TestNG.runSuitesLocally(TestNG.java:1137)
at org.testng.TestNG.runSuites(TestNG.java:1049)
at org.testng.TestNG.run(TestNG.java:1017)
at org.testng.remote.AbstractRemoteTestNG.run(AbstractRemoteTestNG.java:114)
at org.testng.remote.RemoteTestNG.initAndRun(RemoteTestNG.java:251)
at org.testng.remote.RemoteTestNG.main(RemoteTestNG.java:77)
]]>
            </full-stacktrace>
          </exception> <!-- java.lang.AssertionError -->
          <reporter-output>
          </reporter-output>
        </test-method> <!-- loginTest2 -->
        <test-method status="PASS" signature="afterMethod()[pri:0, instance:Test.loginTest@6d64ab]" name="afterMethod" is-config="true" duration-ms="562" started-at="2018-04-22T06:11:35Z" finished-at="2018-04-22T06:11:36Z">
          <reporter-output>
          </reporter-output>
        </test-method> <!-- afterMethod -->
        <test-method status="PASS" signature="beforeMethod()[pri:0, instance:Test.loginTest@6d64ab]" name="beforeMethod" is-config="true" duration-ms="15142" started-at="2018-04-22T06:11:36Z" finished-at="2018-04-22T06:11:51Z">
          <reporter-output>
          </reporter-output>
        </test-method> <!-- beforeMethod -->
        <test-method status="SKIP" signature="loginTest2()[pri:0, instance:Test.loginTest@6d64ab]" name="loginTest2" duration-ms="9296" started-at="2018-04-22T06:11:51Z" finished-at="2018-04-22T06:12:00Z">
          <exception class="java.lang.AssertionError">
            <message>
              <![CDATA[expected [true] but found [false]]]>
            </message>
            <full-stacktrace>
              <![CDATA[java.lang.AssertionError: expected [true] but found [false]
at org.testng.Assert.fail(Assert.java:96)
at org.testng.Assert.failNotEquals(Assert.java:776)
at org.testng.Assert.assertTrue(Assert.java:44)
at org.testng.Assert.assertTrue(Assert.java:54)
at Test.loginTest.loginTest2(loginTest.java:40)
at sun.reflect.NativeMethodAccessorImpl.invoke0(Native Method)
at sun.reflect.NativeMethodAccessorImpl.invoke(Unknown Source)
at sun.reflect.DelegatingMethodAccessorImpl.invoke(Unknown Source)
at java.lang.reflect.Method.invoke(Unknown Source)
at org.testng.internal.MethodInvocationHelper.invokeMethod(MethodInvocationHelper.java:124)
at org.testng.internal.Invoker.invokeMethod(Invoker.java:580)
at org.testng.internal.Invoker.retryFailed(Invoker.java:838)
at org.testng.internal.Invoker.invokeTestMethods(Invoker.java:1009)
at org.testng.internal.TestMethodWorker.invokeTestMethods(TestMethodWorker.java:125)
at org.testng.internal.TestMethodWorker.run(TestMethodWorker.java:109)
at org.testng.TestRunner.privateRun(TestRunner.java:648)
at org.testng.TestRunner.run(TestRunner.java:505)
at org.testng.SuiteRunner.runTest(SuiteRunner.java:455)
at org.testng.SuiteRunner.runSequentially(SuiteRunner.java:450)
at org.testng.SuiteRunner.privateRun(SuiteRunner.java:415)
at org.testng.SuiteRunner.run(SuiteRunner.java:364)
at org.testng.SuiteRunnerWorker.runSuite(SuiteRunnerWorker.java:52)
at org.testng.SuiteRunnerWorker.run(SuiteRunnerWorker.java:84)
at org.testng.TestNG.runSuitesSequentially(TestNG.java:1208)
at org.testng.TestNG.runSuitesLocally(TestNG.java:1137)
at org.testng.TestNG.runSuites(TestNG.java:1049)
at org.testng.TestNG.run(TestNG.java:1017)
at org.testng.remote.AbstractRemoteTestNG.run(AbstractRemoteTestNG.java:114)
at org.testng.remote.RemoteTestNG.initAndRun(RemoteTestNG.java:251)
at org.testng.remote.RemoteTestNG.main(RemoteTestNG.java:77)
]]>
            </full-stacktrace>
          </exception> <!-- java.lang.AssertionError -->
          <reporter-output>
          </reporter-output>
        </test-method> <!-- loginTest2 -->
        <test-method status="PASS" signature="afterMethod()[pri:0, instance:Test.loginTest@6d64ab]" name="afterMethod" is-config="true" duration-ms="2427" started-at="2018-04-22T06:12:00Z" finished-at="2018-04-22T06:12:02Z">
          <reporter-output>
          </reporter-output>
        </test-method> <!-- afterMethod -->
        <test-method status="PASS" signature="beforeMethod()[pri:0, instance:Test.loginTest@6d64ab]" name="beforeMethod" is-config="true" duration-ms="13311" started-at="2018-04-22T06:12:02Z" finished-at="2018-04-22T06:12:16Z">
          <reporter-output>
          </reporter-output>
        </test-method> <!-- beforeMethod -->
        <test-method status="FAIL" signature="loginTest2()[pri:0, instance:Test.loginTest@6d64ab]" name="loginTest2" duration-ms="9688" started-at="2018-04-22T06:12:16Z" finished-at="2018-04-22T06:12:25Z">
          <exception class="java.lang.AssertionError">
            <message>
              <![CDATA[expected [true] but found [false]]]>
            </message>
            <full-stacktrace>
              <![CDATA[java.lang.AssertionError: expected [true] but found [false]
at org.testng.Assert.fail(Assert.java:96)
at org.testng.Assert.failNotEquals(Assert.java:776)
at org.testng.Assert.assertTrue(Assert.java:44)
at org.testng.Assert.assertTrue(Assert.java:54)
at Test.loginTest.loginTest2(loginTest.java:40)
at sun.reflect.NativeMethodAccessorImpl.invoke0(Native Method)
at sun.reflect.NativeMethodAccessorImpl.invoke(Unknown Source)
at sun.reflect.DelegatingMethodAccessorImpl.invoke(Unknown Source)
at java.lang.reflect.Method.invoke(Unknown Source)
at org.testng.internal.MethodInvocationHelper.invokeMethod(MethodInvocationHelper.java:124)
at org.testng.internal.Invoker.invokeMethod(Invoker.java:580)
at org.testng.internal.Invoker.retryFailed(Invoker.java:838)
at org.testng.internal.Invoker.invokeTestMethods(Invoker.java:1009)
at org.testng.internal.TestMethodWorker.invokeTestMethods(TestMethodWorker.java:125)
at org.testng.internal.TestMethodWorker.run(TestMethodWorker.java:109)
at org.testng.TestRunner.privateRun(TestRunner.java:648)
at org.testng.TestRunner.run(TestRunner.java:505)
at org.testng.SuiteRunner.runTest(SuiteRunner.java:455)
at org.testng.SuiteRunner.runSequentially(SuiteRunner.java:450)
at org.testng.SuiteRunner.privateRun(SuiteRunner.java:415)
at org.testng.SuiteRunner.run(SuiteRunner.java:364)
at org.testng.SuiteRunnerWorker.runSuite(SuiteRunnerWorker.java:52)
at org.testng.SuiteRunnerWorker.run(SuiteRunnerWorker.java:84)
at org.testng.TestNG.runSuitesSequentially(TestNG.java:1208)
at org.testng.TestNG.runSuitesLocally(TestNG.java:1137)
at org.testng.TestNG.runSuites(TestNG.java:1049)
at org.testng.TestNG.run(TestNG.java:1017)
at org.testng.remote.AbstractRemoteTestNG.run(AbstractRemoteTestNG.java:114)
at org.testng.remote.RemoteTestNG.initAndRun(RemoteTestNG.java:251)
at org.testng.remote.RemoteTestNG.main(RemoteTestNG.java:77)
]]>
            </full-stacktrace>
          </exception> <!-- java.lang.AssertionError -->
          <reporter-output>
          </reporter-output>
        </test-method> <!-- loginTest2 -->
        <test-method status="PASS" signature="afterMethod()[pri:0, instance:Test.loginTest@6d64ab]" name="afterMethod" is-config="true" duration-ms="2407" started-at="2018-04-22T06:12:26Z" finished-at="2018-04-22T06:12:28Z">
          <reporter-output>
          </reporter-output>
        </test-method> <!-- afterMethod -->
        <test-method status="PASS" signature="beforeMethod()[pri:0, instance:Test.loginTest@6d64ab]" name="beforeMethod" is-config="true" duration-ms="15995" started-at="2018-04-22T06:12:28Z" finished-at="2018-04-22T06:12:44Z">
          <reporter-output>
          </reporter-output>
        </test-method> <!-- beforeMethod -->
        <test-method status="PASS" signature="loginTest1()[pri:1, instance:Test.loginTest@6d64ab]" name="loginTest1" duration-ms="8290" started-at="2018-04-22T06:12:44Z" finished-at="2018-04-22T06:12:52Z">
          <reporter-output>
          </reporter-output>
        </test-method> <!-- loginTest1 -->
        <test-method status="PASS" signature="afterMethod()[pri:0, instance:Test.loginTest@6d64ab]" name="afterMethod" is-config="true" duration-ms="2920" started-at="2018-04-22T06:12:52Z" finished-at="2018-04-22T06:12:55Z">
          <reporter-output>
          </reporter-output>
        </test-method> <!-- afterMethod -->
      </class> <!-- Test.loginTest -->
    </test> <!-- Default test -->
  </suite> <!-- Default suite -->
</testng-results>
