<?xml version="1.0" encoding="UTF-8"?>
<!-- Generated by org.testng.reporters.JUnitXMLReporter -->
<testsuite hostname="ADMIN-PC" ignored="0" name="Default test" tests="6" failures="1" timestamp="22 Apr 2018 06:12:56 GMT" time="158.934" errors="0">
  <testcase name="loginTest2" time="9.152" classname="Test.loginTest">
    <skipped/>
  </testcase> <!-- loginTest2 -->
  <testcase name="loginTest2" time="7.198" classname="Test.loginTest">
    <skipped/>
  </testcase> <!-- loginTest2 -->
  <testcase name="loginTest2" time="7.648" classname="Test.loginTest">
    <skipped/>
  </testcase> <!-- loginTest2 -->
  <testcase name="loginTest2" time="9.296" classname="Test.loginTest">
    <skipped/>
  </testcase> <!-- loginTest2 -->
  <testcase name="loginTest2" time="9.688" classname="Test.loginTest">
    <failure type="java.lang.AssertionError" message="expected [true] but found [false]">
      <![CDATA[java.lang.AssertionError: expected [true] but found [false]
at org.testng.Assert.fail(Assert.java:96)
at org.testng.Assert.failNotEquals(Assert.java:776)
at org.testng.Assert.assertTrue(Assert.java:44)
at org.testng.Assert.assertTrue(Assert.java:54)
at Test.loginTest.loginTest2(loginTest.java:40)
at sun.reflect.NativeMethodAccessorImpl.invoke0(Native Method)
at sun.reflect.NativeMethodAccessorImpl.invoke(Unknown Source)
at sun.reflect.DelegatingMethodAccessorImpl.invoke(Unknown Source)
at java.lang.reflect.Method.invoke(Unknown Source)
at org.testng.internal.MethodInvocationHelper.invokeMethod(MethodInvocationHelper.java:124)
at org.testng.internal.Invoker.invokeMethod(Invoker.java:580)
at org.testng.internal.Invoker.retryFailed(Invoker.java:838)
at org.testng.internal.Invoker.invokeTestMethods(Invoker.java:1009)
at org.testng.internal.TestMethodWorker.invokeTestMethods(TestMethodWorker.java:125)
at org.testng.internal.TestMethodWorker.run(TestMethodWorker.java:109)
at org.testng.TestRunner.privateRun(TestRunner.java:648)
at org.testng.TestRunner.run(TestRunner.java:505)
at org.testng.SuiteRunner.runTest(SuiteRunner.java:455)
at org.testng.SuiteRunner.runSequentially(SuiteRunner.java:450)
at org.testng.SuiteRunner.privateRun(SuiteRunner.java:415)
at org.testng.SuiteRunner.run(SuiteRunner.java:364)
at org.testng.SuiteRunnerWorker.runSuite(SuiteRunnerWorker.java:52)
at org.testng.SuiteRunnerWorker.run(SuiteRunnerWorker.java:84)
at org.testng.TestNG.runSuitesSequentially(TestNG.java:1208)
at org.testng.TestNG.runSuitesLocally(TestNG.java:1137)
at org.testng.TestNG.runSuites(TestNG.java:1049)
at org.testng.TestNG.run(TestNG.java:1017)
at org.testng.remote.AbstractRemoteTestNG.run(AbstractRemoteTestNG.java:114)
at org.testng.remote.RemoteTestNG.initAndRun(RemoteTestNG.java:251)
at org.testng.remote.RemoteTestNG.main(RemoteTestNG.java:77)
]]>
    </failure>
  </testcase> <!-- loginTest2 -->
  <testcase name="loginTest1" time="8.29" classname="Test.loginTest"/>
</testsuite> <!-- Default test -->
